<?xml version="1.0" ?>
<!-- =================================================================================== -->
<!-- |    This document was autogenerated by xacro from /home/jperales/ws_moveit/src/simon_moveit_config/config/simon.urdf.xacro | -->
<!-- |    EDITING THIS FILE BY HAND IS NOT RECOMMENDED                                 | -->
<!-- =================================================================================== -->
<robot name="simon">
    <!-- This is an URDF representation of Simon's robotic arm -->
    <!-- Inertial calculations from https://en.wikipedia.org/wiki/List_of_moments_of_inertia -->
    <material name="blue">
        <color rgba="0 0 0.8 1" />
    </material>
    <material name="green">
        <color rgba="0 0.8 0 1" />
    </material>
    <material name="grey">
        <color rgba="0.6 0.6 0.6 1" />
    </material>
    <!-- World link -->
    <link name="world" />
    <!-- base_joint -->
    <joint name="base_joint" type="fixed">
        <origin rpy="0 0 0" xyz="0 0 0" />
        <parent link="world" />
        <child link="base_link" />
    </joint>
    <!-- base_link is a large rectangular plate -->
    <link name="base_link">
        <visual>
            <origin rpy="0 0 0" xyz="-0.2 0 0.01" />
            <geometry>
                <box size="1 0.5 0.02" />
            </geometry>
            <material name="grey" />
        </visual>
        <collision>
            <origin rpy="0 0 0" xyz="-0.2 0 0.01" />
            <geometry>
                <box size="1 0.5 0.02" />
            </geometry>
        </collision>
        <inertial>
            <mass value="0.1" />
            <origin xyz="0 0 0" rpy="0 0 0" />
            <inertia ixx="0.03" iyy="0.03" izz="0.03" ixy="0.0" ixz="0.0" iyz="0.0" />
        </inertial>
    </link>
    <!-- Fixed joint between base and link_1 -->
    <joint name="base_link_1" type="fixed">
        <origin rpy="0 0 0" xyz="0 0 0.02" />
        <parent link="base_link" />
        <child link="link_1" />
    </joint>
    <link name="link_1">
        <visual>
            <origin rpy="0 0 0" xyz="0 0 0.018" />
            <geometry>
                <cylinder length="0.036" radius="0.01" />
            </geometry>
            <material name="green" />
        </visual>
        <collision>
            <origin rpy="0 0 0" xyz="0 0 0.018" />
            <geometry>
                <cylinder length="0.036" radius="0.01" />
            </geometry>
        </collision>
        <inertial>
            <origin rpy="0 0 0" xyz="0 0 0.018" />
            <mass value="0.3" />
            <inertia ixx="3.9899999999999994e-05" ixy="0.0" ixz="0.0" iyy="3.9899999999999994e-05" iyz="0.0" izz="1.5e-05" />
        </inertial>
    </link>
    <!-- theta_1 allows link_1 to rotate with respect to base_link -->
    <joint name="theta_1" type="revolute">
        <origin rpy="0 0 0" xyz="0 0 0.036" />
        <parent link="link_1" />
        <child link="link_2" />
        <axis xyz="0 0 1" />
        <limit effort="1000.0" lower="-1.5707963267948966" upper="1.5707963267948966" velocity="100" />
    </joint>
    <link name="link_2">
        <visual>
            <origin rpy="0 1.5707963267948966 0" xyz="0.025 0 0" />
            <geometry>
                <cylinder length="0.05" radius="0.01" />
            </geometry>
            <material name="blue" />
        </visual>
        <collision>
            <origin rpy="0 1.5707963267948966 0" xyz="0.025 0 0" />
            <geometry>
                <cylinder length="0.05" radius="0.01" />
            </geometry>
        </collision>
        <inertial>
            <origin rpy="0 1.5707963267948966 0" xyz="0.025 0 0" />
            <mass value="0.4" />
            <inertia ixx="9.333333333333334e-05" ixy="0.0" ixz="0.0" iyy="9.333333333333334e-05" iyz="0.0" izz="2e-05" />
        </inertial>
    </link>
    <!-- theta_2 allows link_3 to rotate with respect to link_2 -->
    <joint name="theta_2" type="revolute">
        <origin rpy="0 0 0" xyz="0.05 0 0" />
        <parent link="link_2" />
        <child link="link_3" />
        <axis xyz="0 1 0" />
        <limit effort="100" lower="-1" upper="1.5707963267948966" velocity="100" />
    </joint>
    <link name="link_3">
        <visual>
            <origin rpy="0 0 0" xyz="0 0 0.2425" />
            <geometry>
                <cylinder length="0.485" radius="0.01" />
            </geometry>
            <material name="green" />
        </visual>
        <collision>
            <origin rpy="0 0 0" xyz="0 0 0.2425" />
            <geometry>
                <cylinder length="0.485" radius="0.01" />
            </geometry>
        </collision>
        <inertial>
            <origin rpy="0 0 0" xyz="0 0 0.2425" />
            <mass value="1" />
            <inertia ixx="0.01962708333333333" ixy="0.0" ixz="0.0" iyy="0.01962708333333333" iyz="0.0" izz="5e-05" />
        </inertial>
    </link>
    <!-- theta_3 allows link_4 to rotate with respect to link_3 -->
    <joint name="theta_3" type="revolute">
        <origin rpy="0 0 0" xyz="0 0 0.485" />
        <parent link="link_3" />
        <child link="link_4" />
        <axis xyz="0 1 0" />
        <limit effort="1000.0" lower="-1.5707963267948966" upper="1" velocity="100" />
    </joint>
    <link name="link_4">
        <visual>
            <origin rpy="0 1.5707963267948966 0" xyz="0.18 0 0" />
            <geometry>
                <cylinder length="0.36" radius="0.01" />
            </geometry>
            <material name="blue" />
        </visual>
        <collision>
            <origin rpy="0 1.5707963267948966 0" xyz="0.18 0 0" />
            <geometry>
                <cylinder length="0.36" radius="0.01" />
            </geometry>
        </collision>
        <inertial>
            <origin rpy="0 1.5707963267948966 0" xyz="0.18 0 0" />
            <mass value="0.75" />
            <inertia ixx="0.00811875" ixy="0.0" ixz="0.0" iyy="0.00811875" iyz="0.0" izz="3.7500000000000003e-05" />
        </inertial>
    </link>
    <!-- theta_4 allows link_5 to rotate with respect to link_4 -->
    <joint name="theta_4" type="continuous">
        <origin rpy="0 0 0" xyz="0.36 0 0" />
        <parent link="link_4" />
        <child link="link_5" />
        <axis xyz="1 0 0" />
    </joint>
    <link name="link_5">
        <visual>
            <origin rpy="0 1.5707963267948966 0" xyz="0.04 0 0" />
            <geometry>
                <cylinder length="0.08" radius="0.01" />
            </geometry>
            <material name="green" />
        </visual>
        <collision>
            <origin rpy="0 1.5707963267948966 0" xyz="0.04 0 0" />
            <geometry>
                <cylinder length="0.08" radius="0.01" />
            </geometry>
        </collision>
        <inertial>
            <origin rpy="0 1.5707963267948966 0" xyz="0.04 0 0" />
            <mass value="0.4" />
            <inertia ixx="0.00022333333333333333" ixy="0.0" ixz="0.0" iyy="0.00022333333333333333" iyz="0.0" izz="2e-05" />
        </inertial>
    </link>
    <transmission name="trans_theta_1">
        <type>transmission_interface/SimpleTransmission</type>
        <joint name="theta_1">
            <hardwareInterface>hardware_interface/PositionJointInterface</hardwareInterface>
        </joint>
        <actuator name="theta_1_motor">
            <hardwareInterface>hardware_interface/PositionJointInterface</hardwareInterface>
            <mechanicalReduction>1</mechanicalReduction>
        </actuator>
    </transmission>
    <transmission name="trans_theta_2">
        <type>transmission_interface/SimpleTransmission</type>
        <joint name="theta_2">
            <hardwareInterface>hardware_interface/PositionJointInterface</hardwareInterface>
        </joint>
        <actuator name="theta_2_motor">
            <hardwareInterface>hardware_interface/PositionJointInterface</hardwareInterface>
            <mechanicalReduction>1</mechanicalReduction>
        </actuator>
    </transmission>
    <transmission name="trans_theta_3">
        <type>transmission_interface/SimpleTransmission</type>
        <joint name="theta_3">
            <hardwareInterface>hardware_interface/PositionJointInterface</hardwareInterface>
        </joint>
        <actuator name="theta_3_motor">
            <hardwareInterface>hardware_interface/PositionJointInterface</hardwareInterface>
            <mechanicalReduction>1</mechanicalReduction>
        </actuator>
    </transmission>
    <transmission name="trans_theta_4">
        <type>transmission_interface/SimpleTransmission</type>
        <joint name="theta_4">
            <hardwareInterface>hardware_interface/EffortJointInterface</hardwareInterface>
        </joint>
        <actuator name="theta_4_motor">
            <hardwareInterface>hardware_interface/EffortJointInterface</hardwareInterface>
            <mechanicalReduction>1</mechanicalReduction>
        </actuator>
    </transmission>
    <gazebo>
        <plugin name="gazebo_ros_control">
            <robotNamespace>/</robotNamespace>
        </plugin>
    </gazebo>
</robot>

